2025-09-20 15:15:54 | INFO | [diag_1758361554_ba62978a] Orchestrator.START | SUCCESS | Workflow initiated for patient 1. | DATA: {"diagnosis_id": "diag_1758361554_ba62978a", "step_name": "Orchestrator", "action": "START", "status": "SUCCESS", "details": "Workflow initiated for patient 1.", "timestamp": "2025-09-20T15:15:54.824363", "metadata": {}}
2025-09-20 15:15:54 | INFO | [diag_1758361554_ba62978a] SymptomAnalyzer.START | SUCCESS | Input state for SymptomAnalyzer received. | DATA: {"diagnosis_id": "diag_1758361554_ba62978a", "step_name": "SymptomAnalyzer", "action": "START", "status": "SUCCESS", "details": "Input state for SymptomAnalyzer received.", "timestamp": "2025-09-20T15:15:54.825928", "metadata": {}}
2025-09-20 15:15:54 | ERROR | [diag_1758361554_ba62978a] SymptomAnalyzer.ERROR | FAILURE | Traceback (most recent call last):
  File "/Users/adityaray/Desktop/AURA/aura-diagnostics/backend/src/workflow.py", line 101, in _safe_step
    result = await func(state)
  File "/Users/adityaray/Desktop/AURA/aura-diagnostics/backend/src/workflow.py", line 114, in _analyze_symptoms
    response = await asyncio.to_thread(
AttributeError: module 'asyncio' has no attribute 'to_thread'
 | DATA: {"diagnosis_id": "diag_1758361554_ba62978a", "step_name": "SymptomAnalyzer", "action": "ERROR", "status": "FAILURE", "details": "Traceback (most recent call last):\n  File \"/Users/adityaray/Desktop/AURA/aura-diagnostics/backend/src/workflow.py\", line 101, in _safe_step\n    result = await func(state)\n  File \"/Users/adityaray/Desktop/AURA/aura-diagnostics/backend/src/workflow.py\", line 114, in _analyze_symptoms\n    response = await asyncio.to_thread(\nAttributeError: module 'asyncio' has no attribute 'to_thread'\n", "timestamp": "2025-09-20T15:15:54.826531", "metadata": {}}
2025-09-20 15:15:54 | ERROR | [diag_1758361554_ba62978a] Orchestrator.FATAL_ERROR | FAILURE | Traceback (most recent call last):
  File "/Users/adityaray/Desktop/AURA/aura-diagnostics/backend/src/workflow.py", line 79, in run
    state.structured_symptoms = await self._safe_step(state, "SymptomAnalyzer", self._analyze_symptoms)
  File "/Users/adityaray/Desktop/AURA/aura-diagnostics/backend/src/workflow.py", line 101, in _safe_step
    result = await func(state)
  File "/Users/adityaray/Desktop/AURA/aura-diagnostics/backend/src/workflow.py", line 114, in _analyze_symptoms
    response = await asyncio.to_thread(
AttributeError: module 'asyncio' has no attribute 'to_thread'
 | DATA: {"diagnosis_id": "diag_1758361554_ba62978a", "step_name": "Orchestrator", "action": "FATAL_ERROR", "status": "FAILURE", "details": "Traceback (most recent call last):\n  File \"/Users/adityaray/Desktop/AURA/aura-diagnostics/backend/src/workflow.py\", line 79, in run\n    state.structured_symptoms = await self._safe_step(state, \"SymptomAnalyzer\", self._analyze_symptoms)\n  File \"/Users/adityaray/Desktop/AURA/aura-diagnostics/backend/src/workflow.py\", line 101, in _safe_step\n    result = await func(state)\n  File \"/Users/adityaray/Desktop/AURA/aura-diagnostics/backend/src/workflow.py\", line 114, in _analyze_symptoms\n    response = await asyncio.to_thread(\nAttributeError: module 'asyncio' has no attribute 'to_thread'\n", "timestamp": "2025-09-20T15:15:54.826778", "metadata": {}}
2025-09-20 15:16:45 | INFO | [diag_1758361605_eb8a0762] Orchestrator.START | SUCCESS | Workflow initiated for patient 1. | DATA: {"diagnosis_id": "diag_1758361605_eb8a0762", "step_name": "Orchestrator", "action": "START", "status": "SUCCESS", "details": "Workflow initiated for patient 1.", "timestamp": "2025-09-20T15:16:45.142386", "metadata": {}}
2025-09-20 15:16:45 | INFO | [diag_1758361605_eb8a0762] SymptomAnalyzer.START | SUCCESS | Input state for SymptomAnalyzer received. | DATA: {"diagnosis_id": "diag_1758361605_eb8a0762", "step_name": "SymptomAnalyzer", "action": "START", "status": "SUCCESS", "details": "Input state for SymptomAnalyzer received.", "timestamp": "2025-09-20T15:16:45.144591", "metadata": {}}
2025-09-20 15:16:45 | ERROR | [diag_1758361605_eb8a0762] SymptomAnalyzer.ERROR | FAILURE | Traceback (most recent call last):
  File "/Users/adityaray/Desktop/AURA/aura-diagnostics/backend/src/workflow.py", line 108, in _safe_step
    result = await func(state)
  File "/Users/adityaray/Desktop/AURA/aura-diagnostics/backend/src/workflow.py", line 121, in _analyze_symptoms
    response = await to_thread(
  File "/Users/adityaray/Desktop/AURA/aura-diagnostics/backend/src/workflow.py", line 22, in to_thread
    return loop.run_in_executor(None, func, *args, **kwargs)
  File "uvloop/loop.pyx", line 2733, in uvloop.loop.Loop.run_in_executor
TypeError: run_in_executor() got an unexpected keyword argument 'model'
 | DATA: {"diagnosis_id": "diag_1758361605_eb8a0762", "step_name": "SymptomAnalyzer", "action": "ERROR", "status": "FAILURE", "details": "Traceback (most recent call last):\n  File \"/Users/adityaray/Desktop/AURA/aura-diagnostics/backend/src/workflow.py\", line 108, in _safe_step\n    result = await func(state)\n  File \"/Users/adityaray/Desktop/AURA/aura-diagnostics/backend/src/workflow.py\", line 121, in _analyze_symptoms\n    response = await to_thread(\n  File \"/Users/adityaray/Desktop/AURA/aura-diagnostics/backend/src/workflow.py\", line 22, in to_thread\n    return loop.run_in_executor(None, func, *args, **kwargs)\n  File \"uvloop/loop.pyx\", line 2733, in uvloop.loop.Loop.run_in_executor\nTypeError: run_in_executor() got an unexpected keyword argument 'model'\n", "timestamp": "2025-09-20T15:16:45.354767", "metadata": {}}
2025-09-20 15:16:45 | ERROR | [diag_1758361605_eb8a0762] Orchestrator.FATAL_ERROR | FAILURE | Traceback (most recent call last):
  File "/Users/adityaray/Desktop/AURA/aura-diagnostics/backend/src/workflow.py", line 86, in run
    state.structured_symptoms = await self._safe_step(state, "SymptomAnalyzer", self._analyze_symptoms)
  File "/Users/adityaray/Desktop/AURA/aura-diagnostics/backend/src/workflow.py", line 108, in _safe_step
    result = await func(state)
  File "/Users/adityaray/Desktop/AURA/aura-diagnostics/backend/src/workflow.py", line 121, in _analyze_symptoms
    response = await to_thread(
  File "/Users/adityaray/Desktop/AURA/aura-diagnostics/backend/src/workflow.py", line 22, in to_thread
    return loop.run_in_executor(None, func, *args, **kwargs)
  File "uvloop/loop.pyx", line 2733, in uvloop.loop.Loop.run_in_executor
TypeError: run_in_executor() got an unexpected keyword argument 'model'
 | DATA: {"diagnosis_id": "diag_1758361605_eb8a0762", "step_name": "Orchestrator", "action": "FATAL_ERROR", "status": "FAILURE", "details": "Traceback (most recent call last):\n  File \"/Users/adityaray/Desktop/AURA/aura-diagnostics/backend/src/workflow.py\", line 86, in run\n    state.structured_symptoms = await self._safe_step(state, \"SymptomAnalyzer\", self._analyze_symptoms)\n  File \"/Users/adityaray/Desktop/AURA/aura-diagnostics/backend/src/workflow.py\", line 108, in _safe_step\n    result = await func(state)\n  File \"/Users/adityaray/Desktop/AURA/aura-diagnostics/backend/src/workflow.py\", line 121, in _analyze_symptoms\n    response = await to_thread(\n  File \"/Users/adityaray/Desktop/AURA/aura-diagnostics/backend/src/workflow.py\", line 22, in to_thread\n    return loop.run_in_executor(None, func, *args, **kwargs)\n  File \"uvloop/loop.pyx\", line 2733, in uvloop.loop.Loop.run_in_executor\nTypeError: run_in_executor() got an unexpected keyword argument 'model'\n", "timestamp": "2025-09-20T15:16:45.356299", "metadata": {}}
2025-09-20 15:17:07 | INFO | [diag_1758361627_eb33daf9] Orchestrator.START | SUCCESS | Workflow initiated for patient 1. | DATA: {"diagnosis_id": "diag_1758361627_eb33daf9", "step_name": "Orchestrator", "action": "START", "status": "SUCCESS", "details": "Workflow initiated for patient 1.", "timestamp": "2025-09-20T15:17:07.940791", "metadata": {}}
2025-09-20 15:17:07 | INFO | [diag_1758361627_eb33daf9] SymptomAnalyzer.START | SUCCESS | Input state for SymptomAnalyzer received. | DATA: {"diagnosis_id": "diag_1758361627_eb33daf9", "step_name": "SymptomAnalyzer", "action": "START", "status": "SUCCESS", "details": "Input state for SymptomAnalyzer received.", "timestamp": "2025-09-20T15:17:07.942077", "metadata": {}}
2025-09-20 15:17:08 | ERROR | [diag_1758361627_eb33daf9] SymptomAnalyzer.ERROR | FAILURE | Traceback (most recent call last):
  File "/Users/adityaray/Desktop/AURA/aura-diagnostics/backend/src/workflow.py", line 112, in _safe_step
    result = await func(state)
  File "/Users/adityaray/Desktop/AURA/aura-diagnostics/backend/src/workflow.py", line 125, in _analyze_symptoms
    response = await to_thread(
  File "/Library/Frameworks/Python.framework/Versions/3.8/lib/python3.8/concurrent/futures/thread.py", line 57, in run
    result = self.fn(*self.args, **self.kwargs)
  File "/Users/adityaray/Desktop/AURA/aura-diagnostics/backend/venv/lib/python3.8/site-packages/openai/_utils/_utils.py", line 286, in wrapper
    return func(*args, **kwargs)
  File "/Users/adityaray/Desktop/AURA/aura-diagnostics/backend/venv/lib/python3.8/site-packages/openai/resources/chat/completions/completions.py", line 1147, in create
    return self._post(
  File "/Users/adityaray/Desktop/AURA/aura-diagnostics/backend/venv/lib/python3.8/site-packages/openai/_base_client.py", line 1259, in post
    return cast(ResponseT, self.request(cast_to, opts, stream=stream, stream_cls=stream_cls))
  File "/Users/adityaray/Desktop/AURA/aura-diagnostics/backend/venv/lib/python3.8/site-packages/openai/_base_client.py", line 1047, in request
    raise self._make_status_error_from_response(err.response) from None
openai.AuthenticationError: Error code: 401 - {'error': {'message': "You didn't provide an API key. You need to provide your API key in an Authorization header using Bearer auth (i.e. Authorization: Bearer YOUR_KEY), or as the password field (with blank username) if you're accessing the API from your browser and are prompted for a username and password. You can obtain an API key from https://platform.openai.com/account/api-keys.", 'type': 'invalid_request_error', 'param': None, 'code': None}}
 | DATA: {"diagnosis_id": "diag_1758361627_eb33daf9", "step_name": "SymptomAnalyzer", "action": "ERROR", "status": "FAILURE", "details": "Traceback (most recent call last):\n  File \"/Users/adityaray/Desktop/AURA/aura-diagnostics/backend/src/workflow.py\", line 112, in _safe_step\n    result = await func(state)\n  File \"/Users/adityaray/Desktop/AURA/aura-diagnostics/backend/src/workflow.py\", line 125, in _analyze_symptoms\n    response = await to_thread(\n  File \"/Library/Frameworks/Python.framework/Versions/3.8/lib/python3.8/concurrent/futures/thread.py\", line 57, in run\n    result = self.fn(*self.args, **self.kwargs)\n  File \"/Users/adityaray/Desktop/AURA/aura-diagnostics/backend/venv/lib/python3.8/site-packages/openai/_utils/_utils.py\", line 286, in wrapper\n    return func(*args, **kwargs)\n  File \"/Users/adityaray/Desktop/AURA/aura-diagnostics/backend/venv/lib/python3.8/site-packages/openai/resources/chat/completions/completions.py\", line 1147, in create\n    return self._post(\n  File \"/Users/adityaray/Desktop/AURA/aura-diagnostics/backend/venv/lib/python3.8/site-packages/openai/_base_client.py\", line 1259, in post\n    return cast(ResponseT, self.request(cast_to, opts, stream=stream, stream_cls=stream_cls))\n  File \"/Users/adityaray/Desktop/AURA/aura-diagnostics/backend/venv/lib/python3.8/site-packages/openai/_base_client.py\", line 1047, in request\n    raise self._make_status_error_from_response(err.response) from None\nopenai.AuthenticationError: Error code: 401 - {'error': {'message': \"You didn't provide an API key. You need to provide your API key in an Authorization header using Bearer auth (i.e. Authorization: Bearer YOUR_KEY), or as the password field (with blank username) if you're accessing the API from your browser and are prompted for a username and password. You can obtain an API key from https://platform.openai.com/account/api-keys.\", 'type': 'invalid_request_error', 'param': None, 'code': None}}\n", "timestamp": "2025-09-20T15:17:08.765874", "metadata": {}}
2025-09-20 15:17:08 | ERROR | [diag_1758361627_eb33daf9] Orchestrator.FATAL_ERROR | FAILURE | Traceback (most recent call last):
  File "/Users/adityaray/Desktop/AURA/aura-diagnostics/backend/src/workflow.py", line 90, in run
    state.structured_symptoms = await self._safe_step(state, "SymptomAnalyzer", self._analyze_symptoms)
  File "/Users/adityaray/Desktop/AURA/aura-diagnostics/backend/src/workflow.py", line 112, in _safe_step
    result = await func(state)
  File "/Users/adityaray/Desktop/AURA/aura-diagnostics/backend/src/workflow.py", line 125, in _analyze_symptoms
    response = await to_thread(
  File "/Library/Frameworks/Python.framework/Versions/3.8/lib/python3.8/concurrent/futures/thread.py", line 57, in run
    result = self.fn(*self.args, **self.kwargs)
  File "/Users/adityaray/Desktop/AURA/aura-diagnostics/backend/venv/lib/python3.8/site-packages/openai/_utils/_utils.py", line 286, in wrapper
    return func(*args, **kwargs)
  File "/Users/adityaray/Desktop/AURA/aura-diagnostics/backend/venv/lib/python3.8/site-packages/openai/resources/chat/completions/completions.py", line 1147, in create
    return self._post(
  File "/Users/adityaray/Desktop/AURA/aura-diagnostics/backend/venv/lib/python3.8/site-packages/openai/_base_client.py", line 1259, in post
    return cast(ResponseT, self.request(cast_to, opts, stream=stream, stream_cls=stream_cls))
  File "/Users/adityaray/Desktop/AURA/aura-diagnostics/backend/venv/lib/python3.8/site-packages/openai/_base_client.py", line 1047, in request
    raise self._make_status_error_from_response(err.response) from None
openai.AuthenticationError: Error code: 401 - {'error': {'message': "You didn't provide an API key. You need to provide your API key in an Authorization header using Bearer auth (i.e. Authorization: Bearer YOUR_KEY), or as the password field (with blank username) if you're accessing the API from your browser and are prompted for a username and password. You can obtain an API key from https://platform.openai.com/account/api-keys.", 'type': 'invalid_request_error', 'param': None, 'code': None}}
 | DATA: {"diagnosis_id": "diag_1758361627_eb33daf9", "step_name": "Orchestrator", "action": "FATAL_ERROR", "status": "FAILURE", "details": "Traceback (most recent call last):\n  File \"/Users/adityaray/Desktop/AURA/aura-diagnostics/backend/src/workflow.py\", line 90, in run\n    state.structured_symptoms = await self._safe_step(state, \"SymptomAnalyzer\", self._analyze_symptoms)\n  File \"/Users/adityaray/Desktop/AURA/aura-diagnostics/backend/src/workflow.py\", line 112, in _safe_step\n    result = await func(state)\n  File \"/Users/adityaray/Desktop/AURA/aura-diagnostics/backend/src/workflow.py\", line 125, in _analyze_symptoms\n    response = await to_thread(\n  File \"/Library/Frameworks/Python.framework/Versions/3.8/lib/python3.8/concurrent/futures/thread.py\", line 57, in run\n    result = self.fn(*self.args, **self.kwargs)\n  File \"/Users/adityaray/Desktop/AURA/aura-diagnostics/backend/venv/lib/python3.8/site-packages/openai/_utils/_utils.py\", line 286, in wrapper\n    return func(*args, **kwargs)\n  File \"/Users/adityaray/Desktop/AURA/aura-diagnostics/backend/venv/lib/python3.8/site-packages/openai/resources/chat/completions/completions.py\", line 1147, in create\n    return self._post(\n  File \"/Users/adityaray/Desktop/AURA/aura-diagnostics/backend/venv/lib/python3.8/site-packages/openai/_base_client.py\", line 1259, in post\n    return cast(ResponseT, self.request(cast_to, opts, stream=stream, stream_cls=stream_cls))\n  File \"/Users/adityaray/Desktop/AURA/aura-diagnostics/backend/venv/lib/python3.8/site-packages/openai/_base_client.py\", line 1047, in request\n    raise self._make_status_error_from_response(err.response) from None\nopenai.AuthenticationError: Error code: 401 - {'error': {'message': \"You didn't provide an API key. You need to provide your API key in an Authorization header using Bearer auth (i.e. Authorization: Bearer YOUR_KEY), or as the password field (with blank username) if you're accessing the API from your browser and are prompted for a username and password. You can obtain an API key from https://platform.openai.com/account/api-keys.\", 'type': 'invalid_request_error', 'param': None, 'code': None}}\n", "timestamp": "2025-09-20T15:17:08.766582", "metadata": {}}
2025-09-20 15:17:54 | INFO | [diag_1758361674_f1754a36] Orchestrator.START | SUCCESS | Workflow initiated for patient 1. | DATA: {"diagnosis_id": "diag_1758361674_f1754a36", "step_name": "Orchestrator", "action": "START", "status": "SUCCESS", "details": "Workflow initiated for patient 1.", "timestamp": "2025-09-20T15:17:54.374946", "metadata": {}}
2025-09-20 15:17:54 | INFO | [diag_1758361674_f1754a36] SymptomAnalyzer.START | SUCCESS | Input state for SymptomAnalyzer received. | DATA: {"diagnosis_id": "diag_1758361674_f1754a36", "step_name": "SymptomAnalyzer", "action": "START", "status": "SUCCESS", "details": "Input state for SymptomAnalyzer received.", "timestamp": "2025-09-20T15:17:54.375446", "metadata": {}}
2025-09-20 15:17:55 | ERROR | [diag_1758361674_f1754a36] SymptomAnalyzer.ERROR | FAILURE | Traceback (most recent call last):
  File "/Users/adityaray/Desktop/AURA/aura-diagnostics/backend/src/workflow.py", line 112, in _safe_step
    result = await func(state)
  File "/Users/adityaray/Desktop/AURA/aura-diagnostics/backend/src/workflow.py", line 125, in _analyze_symptoms
    response = await to_thread(
  File "/Library/Frameworks/Python.framework/Versions/3.8/lib/python3.8/concurrent/futures/thread.py", line 57, in run
    result = self.fn(*self.args, **self.kwargs)
  File "/Users/adityaray/Desktop/AURA/aura-diagnostics/backend/venv/lib/python3.8/site-packages/openai/_utils/_utils.py", line 286, in wrapper
    return func(*args, **kwargs)
  File "/Users/adityaray/Desktop/AURA/aura-diagnostics/backend/venv/lib/python3.8/site-packages/openai/resources/chat/completions/completions.py", line 1147, in create
    return self._post(
  File "/Users/adityaray/Desktop/AURA/aura-diagnostics/backend/venv/lib/python3.8/site-packages/openai/_base_client.py", line 1259, in post
    return cast(ResponseT, self.request(cast_to, opts, stream=stream, stream_cls=stream_cls))
  File "/Users/adityaray/Desktop/AURA/aura-diagnostics/backend/venv/lib/python3.8/site-packages/openai/_base_client.py", line 1047, in request
    raise self._make_status_error_from_response(err.response) from None
openai.AuthenticationError: Error code: 401 - {'error': {'message': "You didn't provide an API key. You need to provide your API key in an Authorization header using Bearer auth (i.e. Authorization: Bearer YOUR_KEY), or as the password field (with blank username) if you're accessing the API from your browser and are prompted for a username and password. You can obtain an API key from https://platform.openai.com/account/api-keys.", 'type': 'invalid_request_error', 'param': None, 'code': None}}
 | DATA: {"diagnosis_id": "diag_1758361674_f1754a36", "step_name": "SymptomAnalyzer", "action": "ERROR", "status": "FAILURE", "details": "Traceback (most recent call last):\n  File \"/Users/adityaray/Desktop/AURA/aura-diagnostics/backend/src/workflow.py\", line 112, in _safe_step\n    result = await func(state)\n  File \"/Users/adityaray/Desktop/AURA/aura-diagnostics/backend/src/workflow.py\", line 125, in _analyze_symptoms\n    response = await to_thread(\n  File \"/Library/Frameworks/Python.framework/Versions/3.8/lib/python3.8/concurrent/futures/thread.py\", line 57, in run\n    result = self.fn(*self.args, **self.kwargs)\n  File \"/Users/adityaray/Desktop/AURA/aura-diagnostics/backend/venv/lib/python3.8/site-packages/openai/_utils/_utils.py\", line 286, in wrapper\n    return func(*args, **kwargs)\n  File \"/Users/adityaray/Desktop/AURA/aura-diagnostics/backend/venv/lib/python3.8/site-packages/openai/resources/chat/completions/completions.py\", line 1147, in create\n    return self._post(\n  File \"/Users/adityaray/Desktop/AURA/aura-diagnostics/backend/venv/lib/python3.8/site-packages/openai/_base_client.py\", line 1259, in post\n    return cast(ResponseT, self.request(cast_to, opts, stream=stream, stream_cls=stream_cls))\n  File \"/Users/adityaray/Desktop/AURA/aura-diagnostics/backend/venv/lib/python3.8/site-packages/openai/_base_client.py\", line 1047, in request\n    raise self._make_status_error_from_response(err.response) from None\nopenai.AuthenticationError: Error code: 401 - {'error': {'message': \"You didn't provide an API key. You need to provide your API key in an Authorization header using Bearer auth (i.e. Authorization: Bearer YOUR_KEY), or as the password field (with blank username) if you're accessing the API from your browser and are prompted for a username and password. You can obtain an API key from https://platform.openai.com/account/api-keys.\", 'type': 'invalid_request_error', 'param': None, 'code': None}}\n", "timestamp": "2025-09-20T15:17:55.074052", "metadata": {}}
2025-09-20 15:17:55 | ERROR | [diag_1758361674_f1754a36] Orchestrator.FATAL_ERROR | FAILURE | Traceback (most recent call last):
  File "/Users/adityaray/Desktop/AURA/aura-diagnostics/backend/src/workflow.py", line 90, in run
    state.structured_symptoms = await self._safe_step(state, "SymptomAnalyzer", self._analyze_symptoms)
  File "/Users/adityaray/Desktop/AURA/aura-diagnostics/backend/src/workflow.py", line 112, in _safe_step
    result = await func(state)
  File "/Users/adityaray/Desktop/AURA/aura-diagnostics/backend/src/workflow.py", line 125, in _analyze_symptoms
    response = await to_thread(
  File "/Library/Frameworks/Python.framework/Versions/3.8/lib/python3.8/concurrent/futures/thread.py", line 57, in run
    result = self.fn(*self.args, **self.kwargs)
  File "/Users/adityaray/Desktop/AURA/aura-diagnostics/backend/venv/lib/python3.8/site-packages/openai/_utils/_utils.py", line 286, in wrapper
    return func(*args, **kwargs)
  File "/Users/adityaray/Desktop/AURA/aura-diagnostics/backend/venv/lib/python3.8/site-packages/openai/resources/chat/completions/completions.py", line 1147, in create
    return self._post(
  File "/Users/adityaray/Desktop/AURA/aura-diagnostics/backend/venv/lib/python3.8/site-packages/openai/_base_client.py", line 1259, in post
    return cast(ResponseT, self.request(cast_to, opts, stream=stream, stream_cls=stream_cls))
  File "/Users/adityaray/Desktop/AURA/aura-diagnostics/backend/venv/lib/python3.8/site-packages/openai/_base_client.py", line 1047, in request
    raise self._make_status_error_from_response(err.response) from None
openai.AuthenticationError: Error code: 401 - {'error': {'message': "You didn't provide an API key. You need to provide your API key in an Authorization header using Bearer auth (i.e. Authorization: Bearer YOUR_KEY), or as the password field (with blank username) if you're accessing the API from your browser and are prompted for a username and password. You can obtain an API key from https://platform.openai.com/account/api-keys.", 'type': 'invalid_request_error', 'param': None, 'code': None}}
 | DATA: {"diagnosis_id": "diag_1758361674_f1754a36", "step_name": "Orchestrator", "action": "FATAL_ERROR", "status": "FAILURE", "details": "Traceback (most recent call last):\n  File \"/Users/adityaray/Desktop/AURA/aura-diagnostics/backend/src/workflow.py\", line 90, in run\n    state.structured_symptoms = await self._safe_step(state, \"SymptomAnalyzer\", self._analyze_symptoms)\n  File \"/Users/adityaray/Desktop/AURA/aura-diagnostics/backend/src/workflow.py\", line 112, in _safe_step\n    result = await func(state)\n  File \"/Users/adityaray/Desktop/AURA/aura-diagnostics/backend/src/workflow.py\", line 125, in _analyze_symptoms\n    response = await to_thread(\n  File \"/Library/Frameworks/Python.framework/Versions/3.8/lib/python3.8/concurrent/futures/thread.py\", line 57, in run\n    result = self.fn(*self.args, **self.kwargs)\n  File \"/Users/adityaray/Desktop/AURA/aura-diagnostics/backend/venv/lib/python3.8/site-packages/openai/_utils/_utils.py\", line 286, in wrapper\n    return func(*args, **kwargs)\n  File \"/Users/adityaray/Desktop/AURA/aura-diagnostics/backend/venv/lib/python3.8/site-packages/openai/resources/chat/completions/completions.py\", line 1147, in create\n    return self._post(\n  File \"/Users/adityaray/Desktop/AURA/aura-diagnostics/backend/venv/lib/python3.8/site-packages/openai/_base_client.py\", line 1259, in post\n    return cast(ResponseT, self.request(cast_to, opts, stream=stream, stream_cls=stream_cls))\n  File \"/Users/adityaray/Desktop/AURA/aura-diagnostics/backend/venv/lib/python3.8/site-packages/openai/_base_client.py\", line 1047, in request\n    raise self._make_status_error_from_response(err.response) from None\nopenai.AuthenticationError: Error code: 401 - {'error': {'message': \"You didn't provide an API key. You need to provide your API key in an Authorization header using Bearer auth (i.e. Authorization: Bearer YOUR_KEY), or as the password field (with blank username) if you're accessing the API from your browser and are prompted for a username and password. You can obtain an API key from https://platform.openai.com/account/api-keys.\", 'type': 'invalid_request_error', 'param': None, 'code': None}}\n", "timestamp": "2025-09-20T15:17:55.075248", "metadata": {}}
2025-09-20 15:18:27 | INFO | [diag_1758361707_ec4aa3be] Orchestrator.START | SUCCESS | Workflow initiated for patient 1. | DATA: {"diagnosis_id": "diag_1758361707_ec4aa3be", "step_name": "Orchestrator", "action": "START", "status": "SUCCESS", "details": "Workflow initiated for patient 1.", "timestamp": "2025-09-20T15:18:27.059757", "metadata": {}}
2025-09-20 15:18:27 | INFO | [diag_1758361707_ec4aa3be] SymptomAnalyzer.START | SUCCESS | Input state for SymptomAnalyzer received. | DATA: {"diagnosis_id": "diag_1758361707_ec4aa3be", "step_name": "SymptomAnalyzer", "action": "START", "status": "SUCCESS", "details": "Input state for SymptomAnalyzer received.", "timestamp": "2025-09-20T15:18:27.060758", "metadata": {}}
2025-09-20 15:18:27 | ERROR | [diag_1758361707_ec4aa3be] SymptomAnalyzer.ERROR | FAILURE | Traceback (most recent call last):
  File "/Users/adityaray/Desktop/AURA/aura-diagnostics/backend/src/workflow.py", line 112, in _safe_step
    result = await func(state)
  File "/Users/adityaray/Desktop/AURA/aura-diagnostics/backend/src/workflow.py", line 125, in _analyze_symptoms
    response = await to_thread(
  File "/Library/Frameworks/Python.framework/Versions/3.8/lib/python3.8/concurrent/futures/thread.py", line 57, in run
    result = self.fn(*self.args, **self.kwargs)
  File "/Users/adityaray/Desktop/AURA/aura-diagnostics/backend/venv/lib/python3.8/site-packages/openai/_utils/_utils.py", line 286, in wrapper
    return func(*args, **kwargs)
  File "/Users/adityaray/Desktop/AURA/aura-diagnostics/backend/venv/lib/python3.8/site-packages/openai/resources/chat/completions/completions.py", line 1147, in create
    return self._post(
  File "/Users/adityaray/Desktop/AURA/aura-diagnostics/backend/venv/lib/python3.8/site-packages/openai/_base_client.py", line 1259, in post
    return cast(ResponseT, self.request(cast_to, opts, stream=stream, stream_cls=stream_cls))
  File "/Users/adityaray/Desktop/AURA/aura-diagnostics/backend/venv/lib/python3.8/site-packages/openai/_base_client.py", line 1047, in request
    raise self._make_status_error_from_response(err.response) from None
openai.AuthenticationError: Error code: 401 - {'error': {'message': "You didn't provide an API key. You need to provide your API key in an Authorization header using Bearer auth (i.e. Authorization: Bearer YOUR_KEY), or as the password field (with blank username) if you're accessing the API from your browser and are prompted for a username and password. You can obtain an API key from https://platform.openai.com/account/api-keys.", 'type': 'invalid_request_error', 'param': None, 'code': None}}
 | DATA: {"diagnosis_id": "diag_1758361707_ec4aa3be", "step_name": "SymptomAnalyzer", "action": "ERROR", "status": "FAILURE", "details": "Traceback (most recent call last):\n  File \"/Users/adityaray/Desktop/AURA/aura-diagnostics/backend/src/workflow.py\", line 112, in _safe_step\n    result = await func(state)\n  File \"/Users/adityaray/Desktop/AURA/aura-diagnostics/backend/src/workflow.py\", line 125, in _analyze_symptoms\n    response = await to_thread(\n  File \"/Library/Frameworks/Python.framework/Versions/3.8/lib/python3.8/concurrent/futures/thread.py\", line 57, in run\n    result = self.fn(*self.args, **self.kwargs)\n  File \"/Users/adityaray/Desktop/AURA/aura-diagnostics/backend/venv/lib/python3.8/site-packages/openai/_utils/_utils.py\", line 286, in wrapper\n    return func(*args, **kwargs)\n  File \"/Users/adityaray/Desktop/AURA/aura-diagnostics/backend/venv/lib/python3.8/site-packages/openai/resources/chat/completions/completions.py\", line 1147, in create\n    return self._post(\n  File \"/Users/adityaray/Desktop/AURA/aura-diagnostics/backend/venv/lib/python3.8/site-packages/openai/_base_client.py\", line 1259, in post\n    return cast(ResponseT, self.request(cast_to, opts, stream=stream, stream_cls=stream_cls))\n  File \"/Users/adityaray/Desktop/AURA/aura-diagnostics/backend/venv/lib/python3.8/site-packages/openai/_base_client.py\", line 1047, in request\n    raise self._make_status_error_from_response(err.response) from None\nopenai.AuthenticationError: Error code: 401 - {'error': {'message': \"You didn't provide an API key. You need to provide your API key in an Authorization header using Bearer auth (i.e. Authorization: Bearer YOUR_KEY), or as the password field (with blank username) if you're accessing the API from your browser and are prompted for a username and password. You can obtain an API key from https://platform.openai.com/account/api-keys.\", 'type': 'invalid_request_error', 'param': None, 'code': None}}\n", "timestamp": "2025-09-20T15:18:27.772677", "metadata": {}}
2025-09-20 15:18:27 | ERROR | [diag_1758361707_ec4aa3be] Orchestrator.FATAL_ERROR | FAILURE | Traceback (most recent call last):
  File "/Users/adityaray/Desktop/AURA/aura-diagnostics/backend/src/workflow.py", line 90, in run
    state.structured_symptoms = await self._safe_step(state, "SymptomAnalyzer", self._analyze_symptoms)
  File "/Users/adityaray/Desktop/AURA/aura-diagnostics/backend/src/workflow.py", line 112, in _safe_step
    result = await func(state)
  File "/Users/adityaray/Desktop/AURA/aura-diagnostics/backend/src/workflow.py", line 125, in _analyze_symptoms
    response = await to_thread(
  File "/Library/Frameworks/Python.framework/Versions/3.8/lib/python3.8/concurrent/futures/thread.py", line 57, in run
    result = self.fn(*self.args, **self.kwargs)
  File "/Users/adityaray/Desktop/AURA/aura-diagnostics/backend/venv/lib/python3.8/site-packages/openai/_utils/_utils.py", line 286, in wrapper
    return func(*args, **kwargs)
  File "/Users/adityaray/Desktop/AURA/aura-diagnostics/backend/venv/lib/python3.8/site-packages/openai/resources/chat/completions/completions.py", line 1147, in create
    return self._post(
  File "/Users/adityaray/Desktop/AURA/aura-diagnostics/backend/venv/lib/python3.8/site-packages/openai/_base_client.py", line 1259, in post
    return cast(ResponseT, self.request(cast_to, opts, stream=stream, stream_cls=stream_cls))
  File "/Users/adityaray/Desktop/AURA/aura-diagnostics/backend/venv/lib/python3.8/site-packages/openai/_base_client.py", line 1047, in request
    raise self._make_status_error_from_response(err.response) from None
openai.AuthenticationError: Error code: 401 - {'error': {'message': "You didn't provide an API key. You need to provide your API key in an Authorization header using Bearer auth (i.e. Authorization: Bearer YOUR_KEY), or as the password field (with blank username) if you're accessing the API from your browser and are prompted for a username and password. You can obtain an API key from https://platform.openai.com/account/api-keys.", 'type': 'invalid_request_error', 'param': None, 'code': None}}
 | DATA: {"diagnosis_id": "diag_1758361707_ec4aa3be", "step_name": "Orchestrator", "action": "FATAL_ERROR", "status": "FAILURE", "details": "Traceback (most recent call last):\n  File \"/Users/adityaray/Desktop/AURA/aura-diagnostics/backend/src/workflow.py\", line 90, in run\n    state.structured_symptoms = await self._safe_step(state, \"SymptomAnalyzer\", self._analyze_symptoms)\n  File \"/Users/adityaray/Desktop/AURA/aura-diagnostics/backend/src/workflow.py\", line 112, in _safe_step\n    result = await func(state)\n  File \"/Users/adityaray/Desktop/AURA/aura-diagnostics/backend/src/workflow.py\", line 125, in _analyze_symptoms\n    response = await to_thread(\n  File \"/Library/Frameworks/Python.framework/Versions/3.8/lib/python3.8/concurrent/futures/thread.py\", line 57, in run\n    result = self.fn(*self.args, **self.kwargs)\n  File \"/Users/adityaray/Desktop/AURA/aura-diagnostics/backend/venv/lib/python3.8/site-packages/openai/_utils/_utils.py\", line 286, in wrapper\n    return func(*args, **kwargs)\n  File \"/Users/adityaray/Desktop/AURA/aura-diagnostics/backend/venv/lib/python3.8/site-packages/openai/resources/chat/completions/completions.py\", line 1147, in create\n    return self._post(\n  File \"/Users/adityaray/Desktop/AURA/aura-diagnostics/backend/venv/lib/python3.8/site-packages/openai/_base_client.py\", line 1259, in post\n    return cast(ResponseT, self.request(cast_to, opts, stream=stream, stream_cls=stream_cls))\n  File \"/Users/adityaray/Desktop/AURA/aura-diagnostics/backend/venv/lib/python3.8/site-packages/openai/_base_client.py\", line 1047, in request\n    raise self._make_status_error_from_response(err.response) from None\nopenai.AuthenticationError: Error code: 401 - {'error': {'message': \"You didn't provide an API key. You need to provide your API key in an Authorization header using Bearer auth (i.e. Authorization: Bearer YOUR_KEY), or as the password field (with blank username) if you're accessing the API from your browser and are prompted for a username and password. You can obtain an API key from https://platform.openai.com/account/api-keys.\", 'type': 'invalid_request_error', 'param': None, 'code': None}}\n", "timestamp": "2025-09-20T15:18:27.773903", "metadata": {}}
2025-09-20 15:21:49 | INFO | [diag_1758361909_e37b1d8e] Orchestrator.START | SUCCESS | Workflow initiated for patient 1. | DATA: {"diagnosis_id": "diag_1758361909_e37b1d8e", "step_name": "Orchestrator", "action": "START", "status": "SUCCESS", "details": "Workflow initiated for patient 1.", "timestamp": "2025-09-20T15:21:49.434342", "metadata": {}}
2025-09-20 15:21:49 | INFO | [diag_1758361909_e37b1d8e] SymptomAnalyzer.START | SUCCESS | Input state for SymptomAnalyzer received. | DATA: {"diagnosis_id": "diag_1758361909_e37b1d8e", "step_name": "SymptomAnalyzer", "action": "START", "status": "SUCCESS", "details": "Input state for SymptomAnalyzer received.", "timestamp": "2025-09-20T15:21:49.435160", "metadata": {}}
2025-09-20 15:21:52 | INFO | [diag_1758361909_e37b1d8e] SymptomAnalyzer.END | SUCCESS | Step completed successfully. | DATA: {"diagnosis_id": "diag_1758361909_e37b1d8e", "step_name": "SymptomAnalyzer", "action": "END", "status": "SUCCESS", "details": "Step completed successfully.", "timestamp": "2025-09-20T15:21:52.252077", "metadata": {}}
2025-09-20 15:21:52 | INFO | [diag_1758361909_e37b1d8e] EHR_Fetcher.START | SUCCESS | Input state for EHR_Fetcher received. | DATA: {"diagnosis_id": "diag_1758361909_e37b1d8e", "step_name": "EHR_Fetcher", "action": "START", "status": "SUCCESS", "details": "Input state for EHR_Fetcher received.", "timestamp": "2025-09-20T15:21:52.252395", "metadata": {}}
2025-09-20 15:21:52 | INFO | [diag_1758361909_e37b1d8e] EHR_Fetcher.END | SUCCESS | Step completed successfully. | DATA: {"diagnosis_id": "diag_1758361909_e37b1d8e", "step_name": "EHR_Fetcher", "action": "END", "status": "SUCCESS", "details": "Step completed successfully.", "timestamp": "2025-09-20T15:21:52.278651", "metadata": {}}
2025-09-20 15:21:52 | INFO | [diag_1758361909_e37b1d8e] LitSearcher.START | SUCCESS | Input state for LitSearcher received. | DATA: {"diagnosis_id": "diag_1758361909_e37b1d8e", "step_name": "LitSearcher", "action": "START", "status": "SUCCESS", "details": "Input state for LitSearcher received.", "timestamp": "2025-09-20T15:21:52.278812", "metadata": {}}
2025-09-20 15:21:56 | INFO | [diag_1758361909_e37b1d8e] LitSearcher.END | SUCCESS | Step completed successfully. | DATA: {"diagnosis_id": "diag_1758361909_e37b1d8e", "step_name": "LitSearcher", "action": "END", "status": "SUCCESS", "details": "Step completed successfully.", "timestamp": "2025-09-20T15:21:56.062065", "metadata": {}}
2025-09-20 15:21:56 | INFO | [diag_1758361909_e37b1d8e] CaseSearcher.START | SUCCESS | Input state for CaseSearcher received. | DATA: {"diagnosis_id": "diag_1758361909_e37b1d8e", "step_name": "CaseSearcher", "action": "START", "status": "SUCCESS", "details": "Input state for CaseSearcher received.", "timestamp": "2025-09-20T15:21:56.063185", "metadata": {}}
2025-09-20 15:21:56 | INFO | [diag_1758361909_e37b1d8e] CaseSearcher.END | SUCCESS | Step completed successfully. | DATA: {"diagnosis_id": "diag_1758361909_e37b1d8e", "step_name": "CaseSearcher", "action": "END", "status": "SUCCESS", "details": "Step completed successfully.", "timestamp": "2025-09-20T15:21:56.063300", "metadata": {}}
2025-09-20 15:21:56 | INFO | [diag_1758361909_e37b1d8e] ReportSynthesizer.START | SUCCESS | Input state for ReportSynthesizer received. | DATA: {"diagnosis_id": "diag_1758361909_e37b1d8e", "step_name": "ReportSynthesizer", "action": "START", "status": "SUCCESS", "details": "Input state for ReportSynthesizer received.", "timestamp": "2025-09-20T15:21:56.063365", "metadata": {}}
2025-09-20 15:21:59 | INFO | [diag_1758361909_e37b1d8e] ReportSynthesizer.END | SUCCESS | Step completed successfully. | DATA: {"diagnosis_id": "diag_1758361909_e37b1d8e", "step_name": "ReportSynthesizer", "action": "END", "status": "SUCCESS", "details": "Step completed successfully.", "timestamp": "2025-09-20T15:21:59.301276", "metadata": {}}
2025-09-20 15:21:59 | INFO | [diag_1758361909_e37b1d8e] DrugChecker.START | SUCCESS | Input state for DrugChecker received. | DATA: {"diagnosis_id": "diag_1758361909_e37b1d8e", "step_name": "DrugChecker", "action": "START", "status": "SUCCESS", "details": "Input state for DrugChecker received.", "timestamp": "2025-09-20T15:21:59.301868", "metadata": {}}
2025-09-20 15:21:59 | INFO | [diag_1758361909_e37b1d8e] DrugChecker.END | SUCCESS | Step completed successfully. | DATA: {"diagnosis_id": "diag_1758361909_e37b1d8e", "step_name": "DrugChecker", "action": "END", "status": "SUCCESS", "details": "Step completed successfully.", "timestamp": "2025-09-20T15:21:59.302047", "metadata": {}}
2025-09-20 15:21:59 | INFO | [diag_1758361909_e37b1d8e] Orchestrator.END | SUCCESS | Workflow completed successfully. | DATA: {"diagnosis_id": "diag_1758361909_e37b1d8e", "step_name": "Orchestrator", "action": "END", "status": "SUCCESS", "details": "Workflow completed successfully.", "timestamp": "2025-09-20T15:21:59.302187", "metadata": {}}
2025-09-20 15:22:26 | INFO | [diag_1758361946_9561cd83] Orchestrator.START | SUCCESS | Workflow initiated for patient 1. | DATA: {"diagnosis_id": "diag_1758361946_9561cd83", "step_name": "Orchestrator", "action": "START", "status": "SUCCESS", "details": "Workflow initiated for patient 1.", "timestamp": "2025-09-20T15:22:26.779927", "metadata": {}}
2025-09-20 15:22:26 | INFO | [diag_1758361946_9561cd83] SymptomAnalyzer.START | SUCCESS | Input state for SymptomAnalyzer received. | DATA: {"diagnosis_id": "diag_1758361946_9561cd83", "step_name": "SymptomAnalyzer", "action": "START", "status": "SUCCESS", "details": "Input state for SymptomAnalyzer received.", "timestamp": "2025-09-20T15:22:26.780255", "metadata": {}}
2025-09-20 15:22:29 | INFO | [diag_1758361946_9561cd83] SymptomAnalyzer.END | SUCCESS | Step completed successfully. | DATA: {"diagnosis_id": "diag_1758361946_9561cd83", "step_name": "SymptomAnalyzer", "action": "END", "status": "SUCCESS", "details": "Step completed successfully.", "timestamp": "2025-09-20T15:22:29.564729", "metadata": {}}
2025-09-20 15:22:29 | INFO | [diag_1758361946_9561cd83] EHR_Fetcher.START | SUCCESS | Input state for EHR_Fetcher received. | DATA: {"diagnosis_id": "diag_1758361946_9561cd83", "step_name": "EHR_Fetcher", "action": "START", "status": "SUCCESS", "details": "Input state for EHR_Fetcher received.", "timestamp": "2025-09-20T15:22:29.565171", "metadata": {}}
2025-09-20 15:22:29 | INFO | [diag_1758361946_9561cd83] EHR_Fetcher.END | SUCCESS | Step completed successfully. | DATA: {"diagnosis_id": "diag_1758361946_9561cd83", "step_name": "EHR_Fetcher", "action": "END", "status": "SUCCESS", "details": "Step completed successfully.", "timestamp": "2025-09-20T15:22:29.591848", "metadata": {}}
2025-09-20 15:22:29 | INFO | [diag_1758361946_9561cd83] LitSearcher.START | SUCCESS | Input state for LitSearcher received. | DATA: {"diagnosis_id": "diag_1758361946_9561cd83", "step_name": "LitSearcher", "action": "START", "status": "SUCCESS", "details": "Input state for LitSearcher received.", "timestamp": "2025-09-20T15:22:29.592028", "metadata": {}}
2025-09-20 15:22:32 | INFO | [diag_1758361946_9561cd83] LitSearcher.END | SUCCESS | Step completed successfully. | DATA: {"diagnosis_id": "diag_1758361946_9561cd83", "step_name": "LitSearcher", "action": "END", "status": "SUCCESS", "details": "Step completed successfully.", "timestamp": "2025-09-20T15:22:32.357752", "metadata": {}}
2025-09-20 15:22:32 | INFO | [diag_1758361946_9561cd83] CaseSearcher.START | SUCCESS | Input state for CaseSearcher received. | DATA: {"diagnosis_id": "diag_1758361946_9561cd83", "step_name": "CaseSearcher", "action": "START", "status": "SUCCESS", "details": "Input state for CaseSearcher received.", "timestamp": "2025-09-20T15:22:32.358906", "metadata": {}}
2025-09-20 15:22:32 | INFO | [diag_1758361946_9561cd83] CaseSearcher.END | SUCCESS | Step completed successfully. | DATA: {"diagnosis_id": "diag_1758361946_9561cd83", "step_name": "CaseSearcher", "action": "END", "status": "SUCCESS", "details": "Step completed successfully.", "timestamp": "2025-09-20T15:22:32.359250", "metadata": {}}
2025-09-20 15:22:32 | INFO | [diag_1758361946_9561cd83] ReportSynthesizer.START | SUCCESS | Input state for ReportSynthesizer received. | DATA: {"diagnosis_id": "diag_1758361946_9561cd83", "step_name": "ReportSynthesizer", "action": "START", "status": "SUCCESS", "details": "Input state for ReportSynthesizer received.", "timestamp": "2025-09-20T15:22:32.359569", "metadata": {}}
2025-09-20 15:22:37 | INFO | [diag_1758361946_9561cd83] ReportSynthesizer.END | SUCCESS | Step completed successfully. | DATA: {"diagnosis_id": "diag_1758361946_9561cd83", "step_name": "ReportSynthesizer", "action": "END", "status": "SUCCESS", "details": "Step completed successfully.", "timestamp": "2025-09-20T15:22:37.903626", "metadata": {}}
2025-09-20 15:22:37 | INFO | [diag_1758361946_9561cd83] DrugChecker.START | SUCCESS | Input state for DrugChecker received. | DATA: {"diagnosis_id": "diag_1758361946_9561cd83", "step_name": "DrugChecker", "action": "START", "status": "SUCCESS", "details": "Input state for DrugChecker received.", "timestamp": "2025-09-20T15:22:37.905031", "metadata": {}}
2025-09-20 15:22:37 | INFO | [diag_1758361946_9561cd83] DrugChecker.END | SUCCESS | Step completed successfully. | DATA: {"diagnosis_id": "diag_1758361946_9561cd83", "step_name": "DrugChecker", "action": "END", "status": "SUCCESS", "details": "Step completed successfully.", "timestamp": "2025-09-20T15:22:37.905123", "metadata": {}}
2025-09-20 15:22:37 | INFO | [diag_1758361946_9561cd83] Orchestrator.END | SUCCESS | Workflow completed successfully. | DATA: {"diagnosis_id": "diag_1758361946_9561cd83", "step_name": "Orchestrator", "action": "END", "status": "SUCCESS", "details": "Workflow completed successfully.", "timestamp": "2025-09-20T15:22:37.905192", "metadata": {}}
2025-09-20 15:55:53 | INFO | [diag_1758363953_72b93b88] Orchestrator.START | SUCCESS | Workflow initiated for patient 1. | DATA: {"diagnosis_id": "diag_1758363953_72b93b88", "step_name": "Orchestrator", "action": "START", "status": "SUCCESS", "details": "Workflow initiated for patient 1.", "timestamp": "2025-09-20T15:55:53.904370", "metadata": {}}
2025-09-20 15:55:53 | INFO | [diag_1758363953_72b93b88] SymptomAnalyzer.START | SUCCESS | Input state for SymptomAnalyzer received. | DATA: {"diagnosis_id": "diag_1758363953_72b93b88", "step_name": "SymptomAnalyzer", "action": "START", "status": "SUCCESS", "details": "Input state for SymptomAnalyzer received.", "timestamp": "2025-09-20T15:55:53.906915", "metadata": {}}
2025-09-20 15:55:56 | INFO | [diag_1758363953_72b93b88] SymptomAnalyzer.END | SUCCESS | Step completed successfully. | DATA: {"diagnosis_id": "diag_1758363953_72b93b88", "step_name": "SymptomAnalyzer", "action": "END", "status": "SUCCESS", "details": "Step completed successfully.", "timestamp": "2025-09-20T15:55:56.535336", "metadata": {}}
2025-09-20 15:55:56 | INFO | [diag_1758363953_72b93b88] EHR_Fetcher.START | SUCCESS | Input state for EHR_Fetcher received. | DATA: {"diagnosis_id": "diag_1758363953_72b93b88", "step_name": "EHR_Fetcher", "action": "START", "status": "SUCCESS", "details": "Input state for EHR_Fetcher received.", "timestamp": "2025-09-20T15:55:56.535837", "metadata": {}}
2025-09-20 15:55:56 | INFO | [diag_1758363953_72b93b88] EHR_Fetcher.END | SUCCESS | Step completed successfully. | DATA: {"diagnosis_id": "diag_1758363953_72b93b88", "step_name": "EHR_Fetcher", "action": "END", "status": "SUCCESS", "details": "Step completed successfully.", "timestamp": "2025-09-20T15:55:56.595830", "metadata": {}}
2025-09-20 15:55:56 | INFO | [diag_1758363953_72b93b88] LitSearcher.START | SUCCESS | Input state for LitSearcher received. | DATA: {"diagnosis_id": "diag_1758363953_72b93b88", "step_name": "LitSearcher", "action": "START", "status": "SUCCESS", "details": "Input state for LitSearcher received.", "timestamp": "2025-09-20T15:55:56.595974", "metadata": {}}
2025-09-20 15:55:59 | INFO | [diag_1758363953_72b93b88] LitSearcher.END | SUCCESS | Step completed successfully. | DATA: {"diagnosis_id": "diag_1758363953_72b93b88", "step_name": "LitSearcher", "action": "END", "status": "SUCCESS", "details": "Step completed successfully.", "timestamp": "2025-09-20T15:55:59.456763", "metadata": {}}
2025-09-20 15:55:59 | INFO | [diag_1758363953_72b93b88] CaseSearcher.SKIPPED | SUCCESS | Case database not yet available. | DATA: {"diagnosis_id": "diag_1758363953_72b93b88", "step_name": "CaseSearcher", "action": "SKIPPED", "status": "SUCCESS", "details": "Case database not yet available.", "timestamp": "2025-09-20T15:55:59.457877", "metadata": {}}
2025-09-20 15:55:59 | INFO | [diag_1758363953_72b93b88] ReportSynthesizer.START | SUCCESS | Input state for ReportSynthesizer received. | DATA: {"diagnosis_id": "diag_1758363953_72b93b88", "step_name": "ReportSynthesizer", "action": "START", "status": "SUCCESS", "details": "Input state for ReportSynthesizer received.", "timestamp": "2025-09-20T15:55:59.458130", "metadata": {}}
2025-09-20 15:55:59 | ERROR | [diag_1758363953_72b93b88] ReportSynthesizer.ERROR | FAILURE | Traceback (most recent call last):
  File "/Users/adityaray/Desktop/AURA/aura-diagnostics/backend/src/workflow.py", line 121, in _safe_step
    result = await func(state)
  File "/Users/adityaray/Desktop/AURA/aura-diagnostics/backend/src/workflow.py", line 193, in _synthesize_report
    prompt = self.prompts.synthesis_report_user(state.to_dict())
  File "/Users/adityaray/Desktop/AURA/aura-diagnostics/backend/src/prompts.py", line 109, in synthesis_report_user
    {format_evidence(literature)}
  File "/Users/adityaray/Desktop/AURA/aura-diagnostics/backend/src/prompts.py", line 87, in format_evidence
    return "\n".join(
  File "/Users/adityaray/Desktop/AURA/aura-diagnostics/backend/src/prompts.py", line 88, in <genexpr>
    f"- (Confidence: {e.get('score', 0):.0%}) {e.get('text', 'N/A')} [Source: {e.get('source', 'N/A')}]"
AttributeError: 'str' object has no attribute 'get'
 | DATA: {"diagnosis_id": "diag_1758363953_72b93b88", "step_name": "ReportSynthesizer", "action": "ERROR", "status": "FAILURE", "details": "Traceback (most recent call last):\n  File \"/Users/adityaray/Desktop/AURA/aura-diagnostics/backend/src/workflow.py\", line 121, in _safe_step\n    result = await func(state)\n  File \"/Users/adityaray/Desktop/AURA/aura-diagnostics/backend/src/workflow.py\", line 193, in _synthesize_report\n    prompt = self.prompts.synthesis_report_user(state.to_dict())\n  File \"/Users/adityaray/Desktop/AURA/aura-diagnostics/backend/src/prompts.py\", line 109, in synthesis_report_user\n    {format_evidence(literature)}\n  File \"/Users/adityaray/Desktop/AURA/aura-diagnostics/backend/src/prompts.py\", line 87, in format_evidence\n    return \"\\n\".join(\n  File \"/Users/adityaray/Desktop/AURA/aura-diagnostics/backend/src/prompts.py\", line 88, in <genexpr>\n    f\"- (Confidence: {e.get('score', 0):.0%}) {e.get('text', 'N/A')} [Source: {e.get('source', 'N/A')}]\"\nAttributeError: 'str' object has no attribute 'get'\n", "timestamp": "2025-09-20T15:55:59.463320", "metadata": {}}
2025-09-20 15:55:59 | ERROR | [diag_1758363953_72b93b88] Orchestrator.FATAL_ERROR | FAILURE | Traceback (most recent call last):
  File "/Users/adityaray/Desktop/AURA/aura-diagnostics/backend/src/workflow.py", line 103, in run
    state.final_report = await self._safe_step(state, "ReportSynthesizer", self._synthesize_report)
  File "/Users/adityaray/Desktop/AURA/aura-diagnostics/backend/src/workflow.py", line 121, in _safe_step
    result = await func(state)
  File "/Users/adityaray/Desktop/AURA/aura-diagnostics/backend/src/workflow.py", line 193, in _synthesize_report
    prompt = self.prompts.synthesis_report_user(state.to_dict())
  File "/Users/adityaray/Desktop/AURA/aura-diagnostics/backend/src/prompts.py", line 109, in synthesis_report_user
    {format_evidence(literature)}
  File "/Users/adityaray/Desktop/AURA/aura-diagnostics/backend/src/prompts.py", line 87, in format_evidence
    return "\n".join(
  File "/Users/adityaray/Desktop/AURA/aura-diagnostics/backend/src/prompts.py", line 88, in <genexpr>
    f"- (Confidence: {e.get('score', 0):.0%}) {e.get('text', 'N/A')} [Source: {e.get('source', 'N/A')}]"
AttributeError: 'str' object has no attribute 'get'
 | DATA: {"diagnosis_id": "diag_1758363953_72b93b88", "step_name": "Orchestrator", "action": "FATAL_ERROR", "status": "FAILURE", "details": "Traceback (most recent call last):\n  File \"/Users/adityaray/Desktop/AURA/aura-diagnostics/backend/src/workflow.py\", line 103, in run\n    state.final_report = await self._safe_step(state, \"ReportSynthesizer\", self._synthesize_report)\n  File \"/Users/adityaray/Desktop/AURA/aura-diagnostics/backend/src/workflow.py\", line 121, in _safe_step\n    result = await func(state)\n  File \"/Users/adityaray/Desktop/AURA/aura-diagnostics/backend/src/workflow.py\", line 193, in _synthesize_report\n    prompt = self.prompts.synthesis_report_user(state.to_dict())\n  File \"/Users/adityaray/Desktop/AURA/aura-diagnostics/backend/src/prompts.py\", line 109, in synthesis_report_user\n    {format_evidence(literature)}\n  File \"/Users/adityaray/Desktop/AURA/aura-diagnostics/backend/src/prompts.py\", line 87, in format_evidence\n    return \"\\n\".join(\n  File \"/Users/adityaray/Desktop/AURA/aura-diagnostics/backend/src/prompts.py\", line 88, in <genexpr>\n    f\"- (Confidence: {e.get('score', 0):.0%}) {e.get('text', 'N/A')} [Source: {e.get('source', 'N/A')}]\"\nAttributeError: 'str' object has no attribute 'get'\n", "timestamp": "2025-09-20T15:55:59.464729", "metadata": {}}
2025-09-20 15:56:37 | INFO | [diag_1758363997_aa8ce785] Orchestrator.START | SUCCESS | Workflow initiated for patient 1. | DATA: {"diagnosis_id": "diag_1758363997_aa8ce785", "step_name": "Orchestrator", "action": "START", "status": "SUCCESS", "details": "Workflow initiated for patient 1.", "timestamp": "2025-09-20T15:56:37.536683", "metadata": {}}
2025-09-20 15:56:37 | INFO | [diag_1758363997_aa8ce785] SymptomAnalyzer.START | SUCCESS | Input state for SymptomAnalyzer received. | DATA: {"diagnosis_id": "diag_1758363997_aa8ce785", "step_name": "SymptomAnalyzer", "action": "START", "status": "SUCCESS", "details": "Input state for SymptomAnalyzer received.", "timestamp": "2025-09-20T15:56:37.537711", "metadata": {}}
2025-09-20 15:56:40 | INFO | [diag_1758363997_aa8ce785] SymptomAnalyzer.END | SUCCESS | Step completed successfully. | DATA: {"diagnosis_id": "diag_1758363997_aa8ce785", "step_name": "SymptomAnalyzer", "action": "END", "status": "SUCCESS", "details": "Step completed successfully.", "timestamp": "2025-09-20T15:56:40.587625", "metadata": {}}
2025-09-20 15:56:40 | INFO | [diag_1758363997_aa8ce785] EHR_Fetcher.START | SUCCESS | Input state for EHR_Fetcher received. | DATA: {"diagnosis_id": "diag_1758363997_aa8ce785", "step_name": "EHR_Fetcher", "action": "START", "status": "SUCCESS", "details": "Input state for EHR_Fetcher received.", "timestamp": "2025-09-20T15:56:40.588009", "metadata": {}}
2025-09-20 15:56:40 | INFO | [diag_1758363997_aa8ce785] EHR_Fetcher.END | SUCCESS | Step completed successfully. | DATA: {"diagnosis_id": "diag_1758363997_aa8ce785", "step_name": "EHR_Fetcher", "action": "END", "status": "SUCCESS", "details": "Step completed successfully.", "timestamp": "2025-09-20T15:56:40.613580", "metadata": {}}
2025-09-20 15:56:40 | INFO | [diag_1758363997_aa8ce785] LitSearcher.START | SUCCESS | Input state for LitSearcher received. | DATA: {"diagnosis_id": "diag_1758363997_aa8ce785", "step_name": "LitSearcher", "action": "START", "status": "SUCCESS", "details": "Input state for LitSearcher received.", "timestamp": "2025-09-20T15:56:40.613706", "metadata": {}}
2025-09-20 15:56:43 | INFO | [diag_1758363997_aa8ce785] LitSearcher.END | SUCCESS | Step completed successfully. | DATA: {"diagnosis_id": "diag_1758363997_aa8ce785", "step_name": "LitSearcher", "action": "END", "status": "SUCCESS", "details": "Step completed successfully.", "timestamp": "2025-09-20T15:56:43.299951", "metadata": {}}
2025-09-20 15:56:43 | INFO | [diag_1758363997_aa8ce785] CaseSearcher.SKIPPED | SUCCESS | Case database not yet available. | DATA: {"diagnosis_id": "diag_1758363997_aa8ce785", "step_name": "CaseSearcher", "action": "SKIPPED", "status": "SUCCESS", "details": "Case database not yet available.", "timestamp": "2025-09-20T15:56:43.300857", "metadata": {}}
2025-09-20 15:56:43 | INFO | [diag_1758363997_aa8ce785] ReportSynthesizer.START | SUCCESS | Input state for ReportSynthesizer received. | DATA: {"diagnosis_id": "diag_1758363997_aa8ce785", "step_name": "ReportSynthesizer", "action": "START", "status": "SUCCESS", "details": "Input state for ReportSynthesizer received.", "timestamp": "2025-09-20T15:56:43.301107", "metadata": {}}
2025-09-20 15:56:48 | INFO | [diag_1758363997_aa8ce785] ReportSynthesizer.END | SUCCESS | Step completed successfully. | DATA: {"diagnosis_id": "diag_1758363997_aa8ce785", "step_name": "ReportSynthesizer", "action": "END", "status": "SUCCESS", "details": "Step completed successfully.", "timestamp": "2025-09-20T15:56:48.033306", "metadata": {}}
2025-09-20 15:56:48 | INFO | [diag_1758363997_aa8ce785] DrugChecker.START | SUCCESS | Input state for DrugChecker received. | DATA: {"diagnosis_id": "diag_1758363997_aa8ce785", "step_name": "DrugChecker", "action": "START", "status": "SUCCESS", "details": "Input state for DrugChecker received.", "timestamp": "2025-09-20T15:56:48.033825", "metadata": {}}
2025-09-20 15:56:48 | INFO | [diag_1758363997_aa8ce785] DrugChecker.END | SUCCESS | Step completed successfully. | DATA: {"diagnosis_id": "diag_1758363997_aa8ce785", "step_name": "DrugChecker", "action": "END", "status": "SUCCESS", "details": "Step completed successfully.", "timestamp": "2025-09-20T15:56:48.033938", "metadata": {}}
2025-09-20 15:56:48 | INFO | [diag_1758363997_aa8ce785] Orchestrator.END | SUCCESS | Workflow completed successfully. | DATA: {"diagnosis_id": "diag_1758363997_aa8ce785", "step_name": "Orchestrator", "action": "END", "status": "SUCCESS", "details": "Workflow completed successfully.", "timestamp": "2025-09-20T15:56:48.034005", "metadata": {}}
